{"trial_id": "1", "hyperparameters": {"space": [{"class_name": "Choice", "config": {"name": "activation", "default": "swish", "conditions": [], "values": ["swish", "relu"], "ordered": false}}, {"class_name": "Choice", "config": {"name": "optimizer", "default": "RMSprop", "conditions": [], "values": ["RMSprop", "Adam"], "ordered": false}}, {"class_name": "Choice", "config": {"name": "learning_rate", "default": 0.01, "conditions": [], "values": [0.01, 0.001, 0.1], "ordered": true}}], "values": {"activation": "swish", "optimizer": "Adam", "learning_rate": 0.001}}, "metrics": {"metrics": {}}, "score": null, "best_step": 0, "status": "FAILED", "message": "Traceback (most recent call last):\n  File \"/opt/anaconda3/lib/python3.12/site-packages/keras_tuner/src/engine/base_tuner.py\", line 274, in _try_run_and_update_trial\n    self._run_and_update_trial(trial, *fit_args, **fit_kwargs)\n  File \"/opt/anaconda3/lib/python3.12/site-packages/keras_tuner/src/engine/base_tuner.py\", line 239, in _run_and_update_trial\n    results = self.run_trial(trial, *fit_args, **fit_kwargs)\n              ^^^^^^^^^^^^^^^^^^^^^^^^^^^^^^^^^^^^^^^^^^^^^^\n  File \"/opt/anaconda3/lib/python3.12/site-packages/keras_tuner/src/engine/tuner.py\", line 314, in run_trial\n    obj_value = self._build_and_fit_model(trial, *args, **copied_kwargs)\n                ^^^^^^^^^^^^^^^^^^^^^^^^^^^^^^^^^^^^^^^^^^^^^^^^^^^^^^^^\n  File \"/opt/anaconda3/lib/python3.12/site-packages/keras_tuner/src/engine/tuner.py\", line 233, in _build_and_fit_model\n    results = self.hypermodel.fit(hp, model, *args, **kwargs)\n              ^^^^^^^^^^^^^^^^^^^^^^^^^^^^^^^^^^^^^^^^^^^^^^^\n  File \"/opt/anaconda3/lib/python3.12/site-packages/keras_tuner/src/engine/hypermodel.py\", line 149, in fit\n    return model.fit(*args, **kwargs)\n           ^^^^^^^^^^^^^^^^^^^^^^^^^^\n  File \"/opt/anaconda3/lib/python3.12/site-packages/keras/src/utils/traceback_utils.py\", line 122, in error_handler\n    raise e.with_traceback(filtered_tb) from None\n  File \"/opt/anaconda3/lib/python3.12/site-packages/keras/src/backend/tensorflow/nn.py\", line 623, in categorical_crossentropy\n    raise ValueError(\nValueError: Arguments `target` and `output` must have the same rank (ndim). Received: target.shape=(None,), output.shape=(None, 11)\n"}